Traceback (most recent call last):
  File "/work/henriksv/code/mario-data-collection/mario_dqn/plots/compare_multiple.py", line 75, in <module>
    ax.plot(x, avg, color=color, label=legends[i])
  File "/home/henriksv/anaconda3/envs/tf2/lib/python3.7/site-packages/matplotlib/axes/_axes.py", line 1665, in plot
    lines = [*self._get_lines(*args, data=data, **kwargs)]
  File "/home/henriksv/anaconda3/envs/tf2/lib/python3.7/site-packages/matplotlib/axes/_base.py", line 225, in __call__
    yield from self._plot_args(this, kwargs)
  File "/home/henriksv/anaconda3/envs/tf2/lib/python3.7/site-packages/matplotlib/axes/_base.py", line 391, in _plot_args
    x, y = self._xy_from_xy(x, y)
  File "/home/henriksv/anaconda3/envs/tf2/lib/python3.7/site-packages/matplotlib/axes/_base.py", line 270, in _xy_from_xy
    "have shapes {} and {}".format(x.shape, y.shape))
ValueError: x and y must have same first dimension, but have shapes (40000,) and (18685,)
srun: error: g001: task 0: Exited with exit code 1
